2018-11-01 13:33:27,930 - ErrorLogs - ERROR - EXCEPTION 403: Bad Dataset connection Params "Failed to establish connection with dataset connector: CSV"
Traceback (most recent call last):
  File "D:/rachit/Blue book/PC.py", line 101, in train_model
    % (json_data["dbconnect"]["name"]), 403)
DatasetConnectionFailed: Failed to establish connection with dataset connector: CSV
2018-11-01 13:34:42,217 - ErrorLogs - ERROR - EXCEPTION 403: Bad Dataset connection Params "Failed to establish connection with dataset connector: CSV"
Traceback (most recent call last):
  File "D:/rachit/Blue book/PC.py", line 101, in train_model
    % (json_data["dbconnect"]["name"]), 403)
DatasetConnectionFailed: Failed to establish connection with dataset connector: CSV
2018-11-01 13:36:22,714 - ErrorLogs - ERROR - EXCEPTION 403: Bad Dataset connection Params "Failed to establish connection with dataset connector: CSV Connect"
Traceback (most recent call last):
  File "D:/rachit/Blue book/PC.py", line 101, in train_model
    % (json_data["dbconnect"]["name"]), 403)
DatasetConnectionFailed: Failed to establish connection with dataset connector: CSV Connect
2018-11-01 14:02:47,553 - ErrorLogs - ERROR - EXCEPTION 500: Damm! Something Blew up
Traceback (most recent call last):
  File "D:/rachit/Blue book/PC.py", line 242, in load_model
    elif LMS.LoadModelService().check_if_model_load(json_data):
  File "D:\rachit\Blue book\handler\LoadModelService.py", line 52, in check_if_model_load
    + "_" + str(load_model_params["appId"]) + ".sav"
KeyError: 'algorithm'
2018-11-01 14:06:08,802 - ErrorLogs - ERROR - EXCEPTION 403: NO such model "Model already loaded"
Traceback (most recent call last):
  File "D:/rachit/Blue book/PC.py", line 243, in load_model
    raise CE.ModelAlreadyInMemory("Model already loaded", 403)
ModelAlreadyInMemory: Model already loaded
2018-11-01 14:19:11,246 - ErrorLogs - ERROR - EXCEPTION 500: Damm! Something Blew up
Traceback (most recent call last):
  File "D:/rachit/Blue book/PC.py", line 323, in predict
    response_json["prediction"] = str(PR.PredictService().predict_service(json_data))
  File "D:\rachit\Blue book\handler\PredictService.py", line 35, in predict_service
    if feature["columnName"] in model_collection_data["categoricalData"]:
KeyError: 'categoricalData'
2018-11-01 14:24:14,368 - ErrorLogs - ERROR - EXCEPTION 403: NO such model "Model not loaded, Please load model"
Traceback (most recent call last):
  File "D:/rachit/Blue book/PC.py", line 321, in predict
    raise CE.ModelNotInMemory("Model not loaded, Please load model", 403)
ModelNotInMemory: Model not loaded, Please load model
2018-11-01 14:26:13,407 - ErrorLogs - ERROR - EXCEPTION 403:Invalid Prediction Params "Model not trained for this feature:DiabetesPedigreeFunction to be categorical. Enter Int value"
Traceback (most recent call last):
  File "D:/rachit/Blue book/PC.py", line 323, in predict
    response_json["prediction"] = str(PR.PredictService().predict_service(json_data))
  File "D:\rachit\Blue book\handler\PredictService.py", line 47, in predict_service
    + " to be categorical. Enter Int value", 403)
InvalidPredictionParams: Model not trained for this feature:DiabetesPedigreeFunction to be categorical. Enter Int value
2018-11-01 14:28:19,658 - ErrorLogs - ERROR - EXCEPTION 500: Damm! Something Blew up
Traceback (most recent call last):
  File "D:/rachit/Blue book/PC.py", line 323, in predict
    response_json["prediction"] = str(PR.PredictService().predict_service(json_data))
  File "D:\rachit\Blue book\handler\PredictService.py", line 65, in predict_service
    if target in model_collection_data["categoricalData"]:
KeyError: 'categoricalData'
2018-11-02 10:25:25,447 - ErrorLogs - ERROR - EXCEPTION 500: Damm! Something Blew up
Traceback (most recent call last):
  File "D:\rachit\Blue book\handler\ModelService.py", line 95, in get_model_details
    if model['deployed'] is not None:
KeyError: 'deployed'
2018-11-02 10:25:25,462 - ErrorLogs - ERROR - EXCEPTION 500: Damm! Something Blew up
Traceback (most recent call last):
  File "D:\rachit\Blue book\handler\ModelService.py", line 95, in get_model_details
    if model['deployed'] is not None:
KeyError: 'deployed'

During handling of the above exception, another exception occurred:

Traceback (most recent call last):
  File "D:/rachit/Blue book/PC.py", line 176, in get_model
    response_json["allModelValues"] = GMS.ModelService().get_model_details(json_data)
  File "D:\rachit\Blue book\handler\ModelService.py", line 103, in get_model_details
    raise Exception("Failed to get all model details: %s" % e.message, 500)
AttributeError: 'KeyError' object has no attribute 'message'
2018-11-02 11:58:43,963 - ErrorLogs - ERROR - EXCEPTION 403: NO such model "Model not loaded, Please load model"
Traceback (most recent call last):
  File "D:/rachit/Blue book/PC.py", line 320, in predict
    raise CE.ModelNotInMemory("Model not loaded, Please load model", 403)
CustomException.CustomException.ModelNotInMemory: Model not loaded, Please load model
2018-11-02 11:58:51,301 - ErrorLogs - ERROR - EXCEPTION 403: NO such model "Model not loaded, Please load model"
Traceback (most recent call last):
  File "D:/rachit/Blue book/PC.py", line 320, in predict
    raise CE.ModelNotInMemory("Model not loaded, Please load model", 403)
CustomException.CustomException.ModelNotInMemory: Model not loaded, Please load model
2018-11-02 11:59:15,305 - ErrorLogs - ERROR - EXCEPTION 403: NO such model "Model not loaded, Please load model"
Traceback (most recent call last):
  File "D:/rachit/Blue book/PC.py", line 320, in predict
    raise CE.ModelNotInMemory("Model not loaded, Please load model", 403)
CustomException.CustomException.ModelNotInMemory: Model not loaded, Please load model
2018-11-02 12:06:12,502 - ErrorLogs - ERROR - EXCEPTION 500: Damm! Something Blew up
Traceback (most recent call last):
  File "D:/rachit/Blue book/PC.py", line 322, in predict
    response_json["prediction"] = str(PR.PredictService().predict_service(json_data))
  File "D:\rachit\Blue book\handler\PredictService.py", line 66, in predict_service
    prediction_list = loaded_model.predict_classes([feature_list])
  File "D:\rachit\Blue book\Blue3\lib\site-packages\keras\engine\sequential.py", line 267, in predict_classes
    proba = self.predict(x, batch_size=batch_size, verbose=verbose)
  File "D:\rachit\Blue book\Blue3\lib\site-packages\keras\engine\training.py", line 1149, in predict
    x, _, _ = self._standardize_user_data(x)
  File "D:\rachit\Blue book\Blue3\lib\site-packages\keras\engine\training.py", line 751, in _standardize_user_data
    exception_prefix='input')
  File "D:\rachit\Blue book\Blue3\lib\site-packages\keras\engine\training_utils.py", line 138, in standardize_input_data
    str(data_shape))
ValueError: Error when checking input: expected dense_1_input to have shape (8,) but got array with shape (1,)
2018-11-02 12:08:07,034 - ErrorLogs - ERROR - EXCEPTION 403: NO such model "Model not deployed, Please deploy model"
Traceback (most recent call last):
  File "D:/rachit/Blue book/PC.py", line 320, in predict
    raise CE.ModelNotInMemory("Model not deployed, Please deploy model", 403)
CustomException.CustomException.ModelNotInMemory: Model not deployed, Please deploy model
2018-11-02 12:08:18,197 - ErrorLogs - ERROR - EXCEPTION 500: Damm! Something Blew up
Traceback (most recent call last):
  File "D:/rachit/Blue book/PC.py", line 322, in predict
    response_json["prediction"] = str(PR.PredictService().predict_service(json_data))
  File "D:\rachit\Blue book\handler\PredictService.py", line 66, in predict_service
    prediction_list = loaded_model.predict_classes(feature_list)
  File "D:\rachit\Blue book\Blue3\lib\site-packages\keras\engine\sequential.py", line 267, in predict_classes
    proba = self.predict(x, batch_size=batch_size, verbose=verbose)
  File "D:\rachit\Blue book\Blue3\lib\site-packages\keras\engine\training.py", line 1149, in predict
    x, _, _ = self._standardize_user_data(x)
  File "D:\rachit\Blue book\Blue3\lib\site-packages\keras\engine\training.py", line 751, in _standardize_user_data
    exception_prefix='input')
  File "D:\rachit\Blue book\Blue3\lib\site-packages\keras\engine\training_utils.py", line 138, in standardize_input_data
    str(data_shape))
ValueError: Error when checking input: expected dense_1_input to have shape (8,) but got array with shape (1,)
2018-11-02 12:09:30,843 - ErrorLogs - ERROR - EXCEPTION 403: NO such model "Model not deployed, Please deploy model"
Traceback (most recent call last):
  File "D:/rachit/Blue book/PC.py", line 320, in predict
    raise CE.ModelNotInMemory("Model not deployed, Please deploy model", 403)
CustomException.CustomException.ModelNotInMemory: Model not deployed, Please deploy model
2018-11-02 12:11:42,417 - ErrorLogs - ERROR - EXCEPTION 500: Damm! Something Blew up
Traceback (most recent call last):
  File "D:/rachit/Blue book/PC.py", line 322, in predict
    response_json["prediction"] = str(PR.PredictService().predict_service(json_data))
  File "D:\rachit\Blue book\handler\PredictService.py", line 66, in predict_service
    prediction_list = loaded_model.predict_classes(feature_list)
  File "D:\rachit\Blue book\Blue3\lib\site-packages\keras\engine\sequential.py", line 267, in predict_classes
    proba = self.predict(x, batch_size=batch_size, verbose=verbose)
  File "D:\rachit\Blue book\Blue3\lib\site-packages\keras\engine\training.py", line 1149, in predict
    x, _, _ = self._standardize_user_data(x)
  File "D:\rachit\Blue book\Blue3\lib\site-packages\keras\engine\training.py", line 751, in _standardize_user_data
    exception_prefix='input')
  File "D:\rachit\Blue book\Blue3\lib\site-packages\keras\engine\training_utils.py", line 138, in standardize_input_data
    str(data_shape))
ValueError: Error when checking input: expected dense_1_input to have shape (8,) but got array with shape (1,)
2018-11-02 12:12:40,135 - ErrorLogs - ERROR - EXCEPTION 500: Damm! Something Blew up
Traceback (most recent call last):
  File "D:/rachit/Blue book/PC.py", line 322, in predict
    response_json["prediction"] = str(PR.PredictService().predict_service(json_data))
  File "D:\rachit\Blue book\handler\PredictService.py", line 67, in predict_service
    prediction_list = loaded_model.predict_classes(feature_list)
  File "D:\rachit\Blue book\Blue3\lib\site-packages\keras\engine\sequential.py", line 267, in predict_classes
    proba = self.predict(x, batch_size=batch_size, verbose=verbose)
  File "D:\rachit\Blue book\Blue3\lib\site-packages\keras\engine\training.py", line 1149, in predict
    x, _, _ = self._standardize_user_data(x)
  File "D:\rachit\Blue book\Blue3\lib\site-packages\keras\engine\training.py", line 751, in _standardize_user_data
    exception_prefix='input')
  File "D:\rachit\Blue book\Blue3\lib\site-packages\keras\engine\training_utils.py", line 138, in standardize_input_data
    str(data_shape))
ValueError: Error when checking input: expected dense_1_input to have shape (8,) but got array with shape (1,)
2018-11-02 12:15:56,080 - ErrorLogs - ERROR - EXCEPTION 500: Damm! Something Blew up
Traceback (most recent call last):
  File "D:/rachit/Blue book/PC.py", line 322, in predict
    response_json["prediction"] = str(PR.PredictService().predict_service(json_data))
  File "D:\rachit\Blue book\handler\PredictService.py", line 68, in predict_service
    prediction_list = loaded_model.predict_classes(np.array(feature_list))
  File "D:\rachit\Blue book\Blue3\lib\site-packages\keras\engine\sequential.py", line 267, in predict_classes
    proba = self.predict(x, batch_size=batch_size, verbose=verbose)
  File "D:\rachit\Blue book\Blue3\lib\site-packages\keras\engine\training.py", line 1149, in predict
    x, _, _ = self._standardize_user_data(x)
  File "D:\rachit\Blue book\Blue3\lib\site-packages\keras\engine\training.py", line 751, in _standardize_user_data
    exception_prefix='input')
  File "D:\rachit\Blue book\Blue3\lib\site-packages\keras\engine\training_utils.py", line 138, in standardize_input_data
    str(data_shape))
ValueError: Error when checking input: expected dense_1_input to have shape (8,) but got array with shape (1,)
2018-11-02 12:16:49,659 - ErrorLogs - ERROR - EXCEPTION 500: Damm! Something Blew up
Traceback (most recent call last):
  File "D:/rachit/Blue book/PC.py", line 322, in predict
    response_json["prediction"] = str(PR.PredictService().predict_service(json_data))
  File "D:\rachit\Blue book\handler\PredictService.py", line 69, in predict_service
    prediction_list = loaded_model.predict_classes(feature_list)
  File "D:\rachit\Blue book\Blue3\lib\site-packages\keras\engine\sequential.py", line 267, in predict_classes
    proba = self.predict(x, batch_size=batch_size, verbose=verbose)
  File "D:\rachit\Blue book\Blue3\lib\site-packages\keras\engine\training.py", line 1149, in predict
    x, _, _ = self._standardize_user_data(x)
  File "D:\rachit\Blue book\Blue3\lib\site-packages\keras\engine\training.py", line 751, in _standardize_user_data
    exception_prefix='input')
  File "D:\rachit\Blue book\Blue3\lib\site-packages\keras\engine\training_utils.py", line 138, in standardize_input_data
    str(data_shape))
ValueError: Error when checking input: expected dense_1_input to have shape (8,) but got array with shape (1,)
2018-11-02 12:22:31,495 - ErrorLogs - ERROR - EXCEPTION 500: Damm! Something Blew up
Traceback (most recent call last):
  File "D:/rachit/Blue book/PC.py", line 322, in predict
    response_json["prediction"] = str(PR.PredictService().predict_service(json_data))
  File "D:\rachit\Blue book\handler\PredictService.py", line 69, in predict_service
    prediction_list = loaded_model.predict_classes(feature_list)
  File "D:\rachit\Blue book\Blue3\lib\site-packages\keras\engine\sequential.py", line 267, in predict_classes
    proba = self.predict(x, batch_size=batch_size, verbose=verbose)
  File "D:\rachit\Blue book\Blue3\lib\site-packages\keras\engine\training.py", line 1149, in predict
    x, _, _ = self._standardize_user_data(x)
  File "D:\rachit\Blue book\Blue3\lib\site-packages\keras\engine\training.py", line 751, in _standardize_user_data
    exception_prefix='input')
  File "D:\rachit\Blue book\Blue3\lib\site-packages\keras\engine\training_utils.py", line 138, in standardize_input_data
    str(data_shape))
ValueError: Error when checking input: expected dense_1_input to have shape (8,) but got array with shape (1,)
2018-11-02 12:22:36,739 - ErrorLogs - ERROR - EXCEPTION 500: Damm! Something Blew up
Traceback (most recent call last):
  File "D:/rachit/Blue book/PC.py", line 322, in predict
    response_json["prediction"] = str(PR.PredictService().predict_service(json_data))
  File "D:\rachit\Blue book\handler\PredictService.py", line 69, in predict_service
    prediction_list = loaded_model.predict_classes(feature_list)
  File "D:\rachit\Blue book\Blue3\lib\site-packages\keras\engine\sequential.py", line 267, in predict_classes
    proba = self.predict(x, batch_size=batch_size, verbose=verbose)
  File "D:\rachit\Blue book\Blue3\lib\site-packages\keras\engine\training.py", line 1149, in predict
    x, _, _ = self._standardize_user_data(x)
  File "D:\rachit\Blue book\Blue3\lib\site-packages\keras\engine\training.py", line 751, in _standardize_user_data
    exception_prefix='input')
  File "D:\rachit\Blue book\Blue3\lib\site-packages\keras\engine\training_utils.py", line 138, in standardize_input_data
    str(data_shape))
ValueError: Error when checking input: expected dense_1_input to have shape (8,) but got array with shape (1,)
2018-11-02 12:22:41,843 - ErrorLogs - ERROR - EXCEPTION 403: NO such model "Model already deployed"
Traceback (most recent call last):
  File "D:/rachit/Blue book/PC.py", line 242, in load_model
    raise CE.ModelAlreadyInMemory("Model already deployed", 403)
CustomException.CustomException.ModelAlreadyInMemory: Model already deployed
2018-11-02 12:23:17,281 - ErrorLogs - ERROR - EXCEPTION 500: Damm! Something Blew up
Traceback (most recent call last):
  File "D:/rachit/Blue book/PC.py", line 322, in predict
    response_json["prediction"] = str(PR.PredictService().predict_service(json_data))
  File "D:\rachit\Blue book\handler\PredictService.py", line 69, in predict_service
    prediction_list = loaded_model.predict_classes(feature_list)
  File "D:\rachit\Blue book\Blue3\lib\site-packages\keras\engine\sequential.py", line 267, in predict_classes
    proba = self.predict(x, batch_size=batch_size, verbose=verbose)
  File "D:\rachit\Blue book\Blue3\lib\site-packages\keras\engine\training.py", line 1149, in predict
    x, _, _ = self._standardize_user_data(x)
  File "D:\rachit\Blue book\Blue3\lib\site-packages\keras\engine\training.py", line 751, in _standardize_user_data
    exception_prefix='input')
  File "D:\rachit\Blue book\Blue3\lib\site-packages\keras\engine\training_utils.py", line 138, in standardize_input_data
    str(data_shape))
ValueError: Error when checking input: expected dense_1_input to have shape (8,) but got array with shape (1,)
2018-11-02 12:26:23,199 - ErrorLogs - ERROR - EXCEPTION 500: Damm! Something Blew up
Traceback (most recent call last):
  File "D:/rachit/Blue book/PC.py", line 322, in predict
    response_json["prediction"] = str(PR.PredictService().predict_service(json_data))
  File "D:\rachit\Blue book\handler\PredictService.py", line 69, in predict_service
    prediction_list = loaded_model.predict_classes(feature_list)
  File "D:\rachit\Blue book\Blue3\lib\site-packages\keras\engine\sequential.py", line 267, in predict_classes
    proba = self.predict(x, batch_size=batch_size, verbose=verbose)
  File "D:\rachit\Blue book\Blue3\lib\site-packages\keras\engine\training.py", line 1164, in predict
    self._make_predict_function()
  File "D:\rachit\Blue book\Blue3\lib\site-packages\keras\engine\training.py", line 554, in _make_predict_function
    **kwargs)
  File "D:\rachit\Blue book\Blue3\lib\site-packages\keras\backend\tensorflow_backend.py", line 2744, in function
    return Function(inputs, outputs, updates=updates, **kwargs)
  File "D:\rachit\Blue book\Blue3\lib\site-packages\keras\backend\tensorflow_backend.py", line 2546, in __init__
    with tf.control_dependencies(self.outputs):
  File "D:\rachit\Blue book\Blue3\lib\site-packages\tensorflow\python\framework\ops.py", line 5002, in control_dependencies
    return get_default_graph().control_dependencies(control_inputs)
  File "D:\rachit\Blue book\Blue3\lib\site-packages\tensorflow\python\framework\ops.py", line 4541, in control_dependencies
    c = self.as_graph_element(c)
  File "D:\rachit\Blue book\Blue3\lib\site-packages\tensorflow\python\framework\ops.py", line 3488, in as_graph_element
    return self._as_graph_element_locked(obj, allow_tensor, allow_operation)
  File "D:\rachit\Blue book\Blue3\lib\site-packages\tensorflow\python\framework\ops.py", line 3567, in _as_graph_element_locked
    raise ValueError("Tensor %s is not an element of this graph." % obj)
ValueError: Tensor Tensor("dense_3/Sigmoid:0", shape=(?, 1), dtype=float32) is not an element of this graph.
2018-11-02 12:28:38,348 - ErrorLogs - ERROR - EXCEPTION 500: Damm! Something Blew up
Traceback (most recent call last):
  File "D:/rachit/Blue book/PC.py", line 322, in predict
    response_json["prediction"] = str(PR.PredictService().predict_service(json_data))
  File "D:\rachit\Blue book\handler\PredictService.py", line 69, in predict_service
    prediction_list = loaded_model.predict_classes(feature_list)
  File "D:\rachit\Blue book\Blue3\lib\site-packages\keras\engine\sequential.py", line 267, in predict_classes
    proba = self.predict(x, batch_size=batch_size, verbose=verbose)
  File "D:\rachit\Blue book\Blue3\lib\site-packages\keras\engine\training.py", line 1164, in predict
    self._make_predict_function()
  File "D:\rachit\Blue book\Blue3\lib\site-packages\keras\engine\training.py", line 554, in _make_predict_function
    **kwargs)
  File "D:\rachit\Blue book\Blue3\lib\site-packages\keras\backend\tensorflow_backend.py", line 2744, in function
    return Function(inputs, outputs, updates=updates, **kwargs)
  File "D:\rachit\Blue book\Blue3\lib\site-packages\keras\backend\tensorflow_backend.py", line 2546, in __init__
    with tf.control_dependencies(self.outputs):
  File "D:\rachit\Blue book\Blue3\lib\site-packages\tensorflow\python\framework\ops.py", line 5002, in control_dependencies
    return get_default_graph().control_dependencies(control_inputs)
  File "D:\rachit\Blue book\Blue3\lib\site-packages\tensorflow\python\framework\ops.py", line 4541, in control_dependencies
    c = self.as_graph_element(c)
  File "D:\rachit\Blue book\Blue3\lib\site-packages\tensorflow\python\framework\ops.py", line 3488, in as_graph_element
    return self._as_graph_element_locked(obj, allow_tensor, allow_operation)
  File "D:\rachit\Blue book\Blue3\lib\site-packages\tensorflow\python\framework\ops.py", line 3567, in _as_graph_element_locked
    raise ValueError("Tensor %s is not an element of this graph." % obj)
ValueError: Tensor Tensor("dense_3/Sigmoid:0", shape=(?, 1), dtype=float32) is not an element of this graph.
2018-11-02 12:30:27,307 - ErrorLogs - ERROR - EXCEPTION 500: Damm! Something Blew up
Traceback (most recent call last):
  File "D:/rachit/Blue book/PC.py", line 322, in predict
    response_json["prediction"] = str(PR.PredictService().predict_service(json_data))
  File "D:\rachit\Blue book\handler\PredictService.py", line 69, in predict_service
    prediction_list = loaded_model.predict_classes([1.,103.,30.,0.183 ,43.1,33.,38., 83.])
  File "D:\rachit\Blue book\Blue3\lib\site-packages\keras\engine\sequential.py", line 267, in predict_classes
    proba = self.predict(x, batch_size=batch_size, verbose=verbose)
  File "D:\rachit\Blue book\Blue3\lib\site-packages\keras\engine\training.py", line 1149, in predict
    x, _, _ = self._standardize_user_data(x)
  File "D:\rachit\Blue book\Blue3\lib\site-packages\keras\engine\training.py", line 751, in _standardize_user_data
    exception_prefix='input')
  File "D:\rachit\Blue book\Blue3\lib\site-packages\keras\engine\training_utils.py", line 138, in standardize_input_data
    str(data_shape))
ValueError: Error when checking input: expected dense_1_input to have shape (8,) but got array with shape (1,)
2018-11-02 12:31:49,529 - ErrorLogs - ERROR - EXCEPTION 500: Damm! Something Blew up
Traceback (most recent call last):
  File "D:/rachit/Blue book/PC.py", line 322, in predict
    response_json["prediction"] = str(PR.PredictService().predict_service(json_data))
  File "D:\rachit\Blue book\handler\PredictService.py", line 69, in predict_service
    prediction_list = loaded_model.predict_classes([[1.,103.,30.,0.183 ,43.1,33.,38., 83.]])
  File "D:\rachit\Blue book\Blue3\lib\site-packages\keras\engine\sequential.py", line 267, in predict_classes
    proba = self.predict(x, batch_size=batch_size, verbose=verbose)
  File "D:\rachit\Blue book\Blue3\lib\site-packages\keras\engine\training.py", line 1149, in predict
    x, _, _ = self._standardize_user_data(x)
  File "D:\rachit\Blue book\Blue3\lib\site-packages\keras\engine\training.py", line 751, in _standardize_user_data
    exception_prefix='input')
  File "D:\rachit\Blue book\Blue3\lib\site-packages\keras\engine\training_utils.py", line 138, in standardize_input_data
    str(data_shape))
ValueError: Error when checking input: expected dense_1_input to have shape (8,) but got array with shape (1,)
2018-11-02 12:32:48,529 - ErrorLogs - ERROR - EXCEPTION 500: Damm! Something Blew up
Traceback (most recent call last):
  File "D:/rachit/Blue book/PC.py", line 322, in predict
    response_json["prediction"] = str(PR.PredictService().predict_service(json_data))
  File "D:\rachit\Blue book\handler\PredictService.py", line 69, in predict_service
    prediction_list = loaded_model.predict_classes(np.array([[1.,103.,30.,0.183 ,43.1,33.,38., 83.]]))
  File "D:\rachit\Blue book\Blue3\lib\site-packages\keras\engine\sequential.py", line 267, in predict_classes
    proba = self.predict(x, batch_size=batch_size, verbose=verbose)
  File "D:\rachit\Blue book\Blue3\lib\site-packages\keras\engine\training.py", line 1164, in predict
    self._make_predict_function()
  File "D:\rachit\Blue book\Blue3\lib\site-packages\keras\engine\training.py", line 554, in _make_predict_function
    **kwargs)
  File "D:\rachit\Blue book\Blue3\lib\site-packages\keras\backend\tensorflow_backend.py", line 2744, in function
    return Function(inputs, outputs, updates=updates, **kwargs)
  File "D:\rachit\Blue book\Blue3\lib\site-packages\keras\backend\tensorflow_backend.py", line 2546, in __init__
    with tf.control_dependencies(self.outputs):
  File "D:\rachit\Blue book\Blue3\lib\site-packages\tensorflow\python\framework\ops.py", line 5002, in control_dependencies
    return get_default_graph().control_dependencies(control_inputs)
  File "D:\rachit\Blue book\Blue3\lib\site-packages\tensorflow\python\framework\ops.py", line 4541, in control_dependencies
    c = self.as_graph_element(c)
  File "D:\rachit\Blue book\Blue3\lib\site-packages\tensorflow\python\framework\ops.py", line 3488, in as_graph_element
    return self._as_graph_element_locked(obj, allow_tensor, allow_operation)
  File "D:\rachit\Blue book\Blue3\lib\site-packages\tensorflow\python\framework\ops.py", line 3567, in _as_graph_element_locked
    raise ValueError("Tensor %s is not an element of this graph." % obj)
ValueError: Tensor Tensor("dense_3/Sigmoid:0", shape=(?, 1), dtype=float32) is not an element of this graph.
2018-11-02 12:34:43,022 - ErrorLogs - ERROR - EXCEPTION 500: Damm! Something Blew up
Traceback (most recent call last):
  File "D:/rachit/Blue book/PC.py", line 322, in predict
    response_json["prediction"] = str(PR.PredictService().predict_service(json_data))
  File "D:\rachit\Blue book\handler\PredictService.py", line 69, in predict_service
    prediction_list = loaded_model._make_predict_function(np.array([[1.,103.,30.,0.183 ,43.1,33.,38., 83.]]))
TypeError: _make_predict_function() takes 1 positional argument but 2 were given
2018-11-02 12:36:14,374 - ErrorLogs - ERROR - EXCEPTION 500: Damm! Something Blew up
Traceback (most recent call last):
  File "D:/rachit/Blue book/PC.py", line 322, in predict
    response_json["prediction"] = str(PR.PredictService().predict_service(json_data))
  File "D:\rachit\Blue book\handler\PredictService.py", line 69, in predict_service
    prediction_list = loaded_model._make_predict_function(feature_list)
TypeError: _make_predict_function() takes 1 positional argument but 2 were given
2018-11-02 12:45:02,900 - ErrorLogs - ERROR - EXCEPTION 500: Damm! Something Blew up
Traceback (most recent call last):
  File "D:/rachit/Blue book/PC.py", line 322, in predict
    response_json["prediction"] = str(PR.PredictService().predict_service(json_data))
  File "D:\rachit\Blue book\handler\PredictService.py", line 68, in predict_service
    with graph.as_default():
NameError: name 'graph' is not defined
2018-11-02 12:46:46,644 - ErrorLogs - ERROR - EXCEPTION 403: NO such model "Model not deployed, Please deploy model"
Traceback (most recent call last):
  File "D:/rachit/Blue book/PC.py", line 320, in predict
    raise CE.ModelNotInMemory("Model not deployed, Please deploy model", 403)
CustomException.CustomException.ModelNotInMemory: Model not deployed, Please deploy model
2018-11-02 12:46:54,973 - ErrorLogs - ERROR - EXCEPTION 500: Damm! Something Blew up
Traceback (most recent call last):
  File "D:/rachit/Blue book/PC.py", line 322, in predict
    response_json["prediction"] = str(PR.PredictService().predict_service(json_data))
  File "D:\rachit\Blue book\handler\PredictService.py", line 68, in predict_service
    with graph.as_default():
NameError: name 'graph' is not defined
2018-11-02 12:48:33,162 - ErrorLogs - ERROR - EXCEPTION 500: Damm! Something Blew up
Traceback (most recent call last):
  File "D:/rachit/Blue book/PC.py", line 322, in predict
    response_json["prediction"] = str(PR.PredictService().predict_service(json_data))
  File "D:\rachit\Blue book\handler\PredictService.py", line 68, in predict_service
    with LMS.LoadModelService().graph.as_default():
AttributeError: 'LoadModelService' object has no attribute 'graph'
2018-11-02 12:51:20,359 - ErrorLogs - ERROR - EXCEPTION 500: Damm! Something Blew up
Traceback (most recent call last):
  File "D:/rachit/Blue book/PC.py", line 322, in predict
    response_json["prediction"] = str(PR.PredictService().predict_service(json_data))
  File "D:\rachit\Blue book\handler\PredictService.py", line 68, in predict_service
    with LMS.LoadModelService().graph.as_default():
AttributeError: 'LoadModelService' object has no attribute 'graph'
2018-11-02 12:52:45,885 - ErrorLogs - ERROR - EXCEPTION 403: NO such model "Model not deployed, Please deploy model"
Traceback (most recent call last):
  File "D:/rachit/Blue book/PC.py", line 320, in predict
    raise CE.ModelNotInMemory("Model not deployed, Please deploy model", 403)
CustomException.CustomException.ModelNotInMemory: Model not deployed, Please deploy model
2018-11-02 12:52:52,172 - ErrorLogs - ERROR - EXCEPTION 500: Damm! Something Blew up
Traceback (most recent call last):
  File "D:/rachit/Blue book/PC.py", line 322, in predict
    response_json["prediction"] = str(PR.PredictService().predict_service(json_data))
  File "D:\rachit\Blue book\handler\PredictService.py", line 68, in predict_service
    with LMS.LoadModelService().graph.as_default():
AttributeError: 'LoadModelService' object has no attribute 'graph'
2018-11-02 12:54:59,560 - ErrorLogs - ERROR - EXCEPTION 500: Damm! Something Blew up
Traceback (most recent call last):
  File "D:/rachit/Blue book/PC.py", line 322, in predict
    response_json["prediction"] = str(PR.PredictService().predict_service(json_data))
  File "D:\rachit\Blue book\handler\PredictService.py", line 69, in predict_service
    with graph.as_default():
NameError: name 'graph' is not defined
2018-11-02 13:16:30,485 - ErrorLogs - ERROR - EXCEPTION 403: NO such model "Model not deployed, Please deploy model"
Traceback (most recent call last):
  File "D:/rachit/Blue book/PC.py", line 320, in predict
    raise CE.ModelNotInMemory("Model not deployed, Please deploy model", 403)
CustomException.CustomException.ModelNotInMemory: Model not deployed, Please deploy model
2018-11-02 13:26:24,869 - ErrorLogs - ERROR - EXCEPTION 403: Bad Algorithm Params "Model name already exist for this app id"
Traceback (most recent call last):
  File "D:/rachit/Blue book/PC.py", line 97, in train_model
    raise CE.BadAlgorithmParams("Model name already exist for this app id", 403)
CustomException.CustomException.BadAlgorithmParams: Model name already exist for this app id
2018-11-02 13:26:45,023 - ErrorLogs - ERROR - EXCEPTION 500: Damm! Something Blew up
Traceback (most recent call last):
  File "D:/rachit/Blue book/PC.py", line 322, in predict
    response_json["prediction"] = str(PR.PredictService().predict_service(json_data))
  File "D:\rachit\Blue book\handler\PredictService.py", line 36, in predict_service
    if 'categoricalData' in model_collection_data or feature["columnName"] in model_collection_data["categoricalData"]:
KeyError: 'categoricalData'
2018-11-02 14:02:03,192 - ErrorLogs - ERROR - EXCEPTION 403: Bad Algorithm Params "Model name already exist for this app id"
Traceback (most recent call last):
  File "D:/rachit/Blue book/PC.py", line 97, in train_model
    raise CE.BadAlgorithmParams("Model name already exist for this app id", 403)
CustomException.CustomException.BadAlgorithmParams: Model name already exist for this app id
2018-11-02 14:04:32,018 - ErrorLogs - ERROR - EXCEPTION 403: Bad Algorithm Params "Model name already exist for this app id"
Traceback (most recent call last):
  File "D:/rachit/Blue book/PC.py", line 97, in train_model
    raise CE.BadAlgorithmParams("Model name already exist for this app id", 403)
CustomException.CustomException.BadAlgorithmParams: Model name already exist for this app id
2018-11-02 14:11:26,540 - ErrorLogs - ERROR - EXCEPTION 403: Bad Algorithm Params "Model name already exist for this app id"
Traceback (most recent call last):
  File "D:/rachit/Blue book/PC.py", line 97, in train_model
    raise CE.BadAlgorithmParams("Model name already exist for this app id", 403)
CustomException.CustomException.BadAlgorithmParams: Model name already exist for this app id
2018-11-02 14:13:25,372 - ErrorLogs - ERROR - EXCEPTION 403: Bad Algorithm Params "Model name already exist for this app id"
Traceback (most recent call last):
  File "D:/rachit/Blue book/PC.py", line 97, in train_model
    raise CE.BadAlgorithmParams("Model name already exist for this app id", 403)
CustomException.CustomException.BadAlgorithmParams: Model name already exist for this app id
2018-11-02 14:57:59,672 - ErrorLogs - ERROR - EXCEPTION 500: Damm! Something Blew up "('activationInputLayer',)"
Traceback (most recent call last):
  File "D:\rachit\Blue book\handler\TrainService.py", line 49, in train_model
    model_dict = AF.AlgorithmFactory().algorithm(selected_algorithm).train(split_params, model_dict)
  File "D:\rachit\Blue book\Algorithms\NeuralNetwork.py", line 28, in train
    trained_model.add(Dense(12, input_dim=len(split_params["features_train"].columns), activation=model_dict["algorithm"]["parameters"]["activationInputLayer"]))
KeyError: 'activationInputLayer'
2018-11-02 14:59:44,513 - ErrorLogs - ERROR - EXCEPTION 403: Bad Algorithm Params "Model name already exist for this app id"
Traceback (most recent call last):
  File "D:/rachit/Blue book/PC.py", line 97, in train_model
    raise CE.BadAlgorithmParams("Model name already exist for this app id", 403)
CustomException.CustomException.BadAlgorithmParams: Model name already exist for this app id
2018-11-02 14:59:52,009 - ErrorLogs - ERROR - EXCEPTION 500: Damm! Something Blew up "('activationInputLayer',)"
Traceback (most recent call last):
  File "D:\rachit\Blue book\handler\TrainService.py", line 49, in train_model
    model_dict = AF.AlgorithmFactory().algorithm(selected_algorithm).train(split_params, model_dict)
  File "D:\rachit\Blue book\Algorithms\NeuralNetwork.py", line 29, in train
    trained_model.add(Dense(12, input_dim=len(split_params["features_train"].columns), activation=model_dict["algorithm"]["parameters"]["activationInputLayer"]))
KeyError: 'activationInputLayer'
2018-11-02 15:02:34,474 - ErrorLogs - ERROR - EXCEPTION 403: Bad Algorithm Params "Model name already exist for this app id"
Traceback (most recent call last):
  File "D:/rachit/Blue book/PC.py", line 97, in train_model
    raise CE.BadAlgorithmParams("Model name already exist for this app id", 403)
CustomException.CustomException.BadAlgorithmParams: Model name already exist for this app id
2018-11-02 15:02:41,897 - ErrorLogs - ERROR - EXCEPTION 500: Damm! Something Blew up "('string indices must be integers',)"
Traceback (most recent call last):
  File "D:\rachit\Blue book\handler\TrainService.py", line 49, in train_model
    model_dict = AF.AlgorithmFactory().algorithm(selected_algorithm).train(split_params, model_dict)
  File "D:\rachit\Blue book\Algorithms\NeuralNetwork.py", line 31, in train
    for hiddenLayer in model_dict["algorithm"]["parameters"]["activationOutputLayer"]["hiddenLayers"]:
TypeError: string indices must be integers
2018-11-02 15:04:48,028 - ErrorLogs - ERROR - EXCEPTION 500: Damm! Something Blew up "('string indices must be integers',)"
Traceback (most recent call last):
  File "D:\rachit\Blue book\handler\TrainService.py", line 49, in train_model
    model_dict = AF.AlgorithmFactory().algorithm(selected_algorithm).train(split_params, model_dict)
  File "D:\rachit\Blue book\Algorithms\NeuralNetwork.py", line 31, in train
    for hiddenLayer in model_dict["algorithm"]["parameters"]["activationOutputLayer"]["hiddenLayers"]:
TypeError: string indices must be integers
2018-11-02 15:05:49,605 - ErrorLogs - ERROR - EXCEPTION 500: Damm! Something Blew up "("malformed node or string: {'type': 'dense', 'neurons': 8, 'activation': 'relu'}",)"
Traceback (most recent call last):
  File "D:\rachit\Blue book\handler\TrainService.py", line 49, in train_model
    model_dict = AF.AlgorithmFactory().algorithm(selected_algorithm).train(split_params, model_dict)
  File "D:\rachit\Blue book\Algorithms\NeuralNetwork.py", line 32, in train
    hiddenLayer = ast.literal_eval(hiddenLayer)
  File "C:\Users\rachit.bedi\AppData\Local\Programs\Python\Python36\lib\ast.py", line 85, in literal_eval
    return _convert(node_or_string)
  File "C:\Users\rachit.bedi\AppData\Local\Programs\Python\Python36\lib\ast.py", line 84, in _convert
    raise ValueError('malformed node or string: ' + repr(node))
ValueError: malformed node or string: {'type': 'dense', 'neurons': 8, 'activation': 'relu'}
2018-11-02 15:06:36,013 - ErrorLogs - ERROR - EXCEPTION 500: Damm! Something Blew up "("'str' object is not callable",)"
Traceback (most recent call last):
  File "D:\rachit\Blue book\handler\TrainService.py", line 49, in train_model
    model_dict = AF.AlgorithmFactory().algorithm(selected_algorithm).train(split_params, model_dict)
  File "D:\rachit\Blue book\Algorithms\NeuralNetwork.py", line 32, in train
    trained_model.add(hiddenLayer["type"](hiddenLayer["neurons"], activation=hiddenLayer["activation"]))
TypeError: 'str' object is not callable
2018-11-02 15:07:30,805 - ErrorLogs - ERROR - EXCEPTION 403: Bad Algorithm Params "Model name already exist for this app id"
Traceback (most recent call last):
  File "D:/rachit/Blue book/PC.py", line 97, in train_model
    raise CE.BadAlgorithmParams("Model name already exist for this app id", 403)
CustomException.CustomException.BadAlgorithmParams: Model name already exist for this app id
2018-11-02 15:07:40,289 - ErrorLogs - ERROR - EXCEPTION 500: Damm! Something Blew up "("malformed node or string: {'type': 'dense', 'neurons': 8, 'activation': 'relu'}",)"
Traceback (most recent call last):
  File "D:\rachit\Blue book\handler\TrainService.py", line 49, in train_model
    model_dict = AF.AlgorithmFactory().algorithm(selected_algorithm).train(split_params, model_dict)
  File "D:\rachit\Blue book\Algorithms\NeuralNetwork.py", line 33, in train
    hiddenLayer = ast.literal_eval(hiddenLayer)
  File "C:\Users\rachit.bedi\AppData\Local\Programs\Python\Python36\lib\ast.py", line 85, in literal_eval
    return _convert(node_or_string)
  File "C:\Users\rachit.bedi\AppData\Local\Programs\Python\Python36\lib\ast.py", line 84, in _convert
    raise ValueError('malformed node or string: ' + repr(node))
ValueError: malformed node or string: {'type': 'dense', 'neurons': 8, 'activation': 'relu'}
2018-11-02 15:11:20,868 - ErrorLogs - ERROR - EXCEPTION 403: Bad Algorithm Params "Model name already exist for this app id"
Traceback (most recent call last):
  File "D:/rachit/Blue book/PC.py", line 97, in train_model
    raise CE.BadAlgorithmParams("Model name already exist for this app id", 403)
CustomException.CustomException.BadAlgorithmParams: Model name already exist for this app id
2018-11-02 15:11:27,459 - ErrorLogs - ERROR - EXCEPTION 500: Damm! Something Blew up "("malformed node or string: {'type': 'dense', 'neurons': '8', 'activation': 'relu'}",)"
Traceback (most recent call last):
  File "D:\rachit\Blue book\handler\TrainService.py", line 49, in train_model
    model_dict = AF.AlgorithmFactory().algorithm(selected_algorithm).train(split_params, model_dict)
  File "D:\rachit\Blue book\Algorithms\NeuralNetwork.py", line 33, in train
    hiddenLayer = ast.literal_eval(hiddenLayer)
  File "C:\Users\rachit.bedi\AppData\Local\Programs\Python\Python36\lib\ast.py", line 85, in literal_eval
    return _convert(node_or_string)
  File "C:\Users\rachit.bedi\AppData\Local\Programs\Python\Python36\lib\ast.py", line 84, in _convert
    raise ValueError('malformed node or string: ' + repr(node))
ValueError: malformed node or string: {'type': 'dense', 'neurons': '8', 'activation': 'relu'}
2018-11-02 15:13:37,147 - ErrorLogs - ERROR - EXCEPTION 500: Damm! Something Blew up "("the JSON object must be str, bytes or bytearray, not 'dict'",)"
Traceback (most recent call last):
  File "D:\rachit\Blue book\handler\TrainService.py", line 49, in train_model
    model_dict = AF.AlgorithmFactory().algorithm(selected_algorithm).train(split_params, model_dict)
  File "D:\rachit\Blue book\Algorithms\NeuralNetwork.py", line 33, in train
    hiddenLayer = json.loads(hiddenLayer)
  File "C:\Users\rachit.bedi\AppData\Local\Programs\Python\Python36\lib\json\__init__.py", line 348, in loads
    'not {!r}'.format(s.__class__.__name__))
TypeError: the JSON object must be str, bytes or bytearray, not 'dict'
2018-11-02 15:14:46,696 - ErrorLogs - ERROR - EXCEPTION 500: Damm! Something Blew up "('Expecting property name enclosed in double quotes: line 1 column 2 (char 1)',)"
Traceback (most recent call last):
  File "D:\rachit\Blue book\handler\TrainService.py", line 49, in train_model
    model_dict = AF.AlgorithmFactory().algorithm(selected_algorithm).train(split_params, model_dict)
  File "D:\rachit\Blue book\Algorithms\NeuralNetwork.py", line 32, in train
    hiddenLayer = json.loads(str(hiddenLayer))
  File "C:\Users\rachit.bedi\AppData\Local\Programs\Python\Python36\lib\json\__init__.py", line 354, in loads
    return _default_decoder.decode(s)
  File "C:\Users\rachit.bedi\AppData\Local\Programs\Python\Python36\lib\json\decoder.py", line 339, in decode
    obj, end = self.raw_decode(s, idx=_w(s, 0).end())
  File "C:\Users\rachit.bedi\AppData\Local\Programs\Python\Python36\lib\json\decoder.py", line 355, in raw_decode
    obj, end = self.scan_once(s, idx)
json.decoder.JSONDecodeError: Expecting property name enclosed in double quotes: line 1 column 2 (char 1)
2018-11-02 15:16:13,825 - ErrorLogs - ERROR - EXCEPTION 500: Damm! Something Blew up "('Expecting property name enclosed in double quotes: line 1 column 2 (char 1)',)"
Traceback (most recent call last):
  File "D:\rachit\Blue book\handler\TrainService.py", line 49, in train_model
    model_dict = AF.AlgorithmFactory().algorithm(selected_algorithm).train(split_params, model_dict)
  File "D:\rachit\Blue book\Algorithms\NeuralNetwork.py", line 32, in train
    hiddenLayer = json.loads(str(hiddenLayer))
  File "C:\Users\rachit.bedi\AppData\Local\Programs\Python\Python36\lib\json\__init__.py", line 354, in loads
    return _default_decoder.decode(s)
  File "C:\Users\rachit.bedi\AppData\Local\Programs\Python\Python36\lib\json\decoder.py", line 339, in decode
    obj, end = self.raw_decode(s, idx=_w(s, 0).end())
  File "C:\Users\rachit.bedi\AppData\Local\Programs\Python\Python36\lib\json\decoder.py", line 355, in raw_decode
    obj, end = self.scan_once(s, idx)
json.decoder.JSONDecodeError: Expecting property name enclosed in double quotes: line 1 column 2 (char 1)
2018-11-02 15:16:43,251 - ErrorLogs - ERROR - EXCEPTION 500: Damm! Something Blew up "("malformed node or string: {'type': 'dense', 'neurons': '8', 'activation': 'relu'}",)"
Traceback (most recent call last):
  File "D:\rachit\Blue book\handler\TrainService.py", line 49, in train_model
    model_dict = AF.AlgorithmFactory().algorithm(selected_algorithm).train(split_params, model_dict)
  File "D:\rachit\Blue book\Algorithms\NeuralNetwork.py", line 33, in train
    hiddenLayer = ast.literal_eval(hiddenLayer)
  File "C:\Users\rachit.bedi\AppData\Local\Programs\Python\Python36\lib\ast.py", line 85, in literal_eval
    return _convert(node_or_string)
  File "C:\Users\rachit.bedi\AppData\Local\Programs\Python\Python36\lib\ast.py", line 84, in _convert
    raise ValueError('malformed node or string: ' + repr(node))
ValueError: malformed node or string: {'type': 'dense', 'neurons': '8', 'activation': 'relu'}
2018-11-02 15:18:34,070 - ErrorLogs - ERROR - EXCEPTION 500: Damm! Something Blew up "("'str' object is not callable",)"
Traceback (most recent call last):
  File "D:\rachit\Blue book\handler\TrainService.py", line 49, in train_model
    model_dict = AF.AlgorithmFactory().algorithm(selected_algorithm).train(split_params, model_dict)
  File "D:\rachit\Blue book\Algorithms\NeuralNetwork.py", line 34, in train
    trained_model.add(hiddenLayer["type"](hiddenLayer["neurons"], activation=hiddenLayer["activation"]))
TypeError: 'str' object is not callable
2018-11-02 15:20:24,468 - ErrorLogs - ERROR - EXCEPTION 500: Damm! Something Blew up "("'str' object is not callable",)"
Traceback (most recent call last):
  File "D:\rachit\Blue book\handler\TrainService.py", line 49, in train_model
    model_dict = AF.AlgorithmFactory().algorithm(selected_algorithm).train(split_params, model_dict)
  File "D:\rachit\Blue book\Algorithms\NeuralNetwork.py", line 34, in train
    trained_model.add(hiddenLayer["type"](hiddenLayer["neurons"], activation=hiddenLayer["activation"]))
TypeError: 'str' object is not callable
2018-11-02 15:22:29,243 - ErrorLogs - ERROR - EXCEPTION 500: Damm! Something Blew up "("'str' object is not callable",)"
Traceback (most recent call last):
  File "D:\rachit\Blue book\handler\TrainService.py", line 49, in train_model
    model_dict = AF.AlgorithmFactory().algorithm(selected_algorithm).train(split_params, model_dict)
  File "D:\rachit\Blue book\Algorithms\NeuralNetwork.py", line 35, in train
    trained_model.add(hiddenLayer["type"](hiddenLayer["neurons"], activation=hiddenLayer["activation"]))
TypeError: 'str' object is not callable
2018-11-02 15:23:37,088 - ErrorLogs - ERROR - EXCEPTION 403: Bad Algorithm Params "Model name already exist for this app id"
Traceback (most recent call last):
  File "D:/rachit/Blue book/PC.py", line 97, in train_model
    raise CE.BadAlgorithmParams("Model name already exist for this app id", 403)
CustomException.CustomException.BadAlgorithmParams: Model name already exist for this app id
2018-11-02 15:23:44,713 - ErrorLogs - ERROR - EXCEPTION 500: Damm! Something Blew up "("'str' object is not callable",)"
Traceback (most recent call last):
  File "D:\rachit\Blue book\handler\TrainService.py", line 49, in train_model
    model_dict = AF.AlgorithmFactory().algorithm(selected_algorithm).train(split_params, model_dict)
  File "D:\rachit\Blue book\Algorithms\NeuralNetwork.py", line 35, in train
    trained_model.add(hiddenLayer["type"](hiddenLayer["neurons"], activation=hiddenLayer["activation"]))
TypeError: 'str' object is not callable
2018-11-02 15:28:25,786 - ErrorLogs - ERROR - EXCEPTION 403: NO such model "Model not deployed, Please deploy model"
Traceback (most recent call last):
  File "D:/rachit/Blue book/PC.py", line 320, in predict
    raise CE.ModelNotInMemory("Model not deployed, Please deploy model", 403)
CustomException.CustomException.ModelNotInMemory: Model not deployed, Please deploy model
2018-11-02 15:28:38,710 - ErrorLogs - ERROR - EXCEPTION 500: Damm! Something Blew up
Traceback (most recent call last):
  File "D:\rachit\Blue book\Blue3\lib\site-packages\tensorflow\python\client\session.py", line 1050, in _run
    subfeed, allow_tensor=True, allow_operation=False)
  File "D:\rachit\Blue book\Blue3\lib\site-packages\tensorflow\python\framework\ops.py", line 3488, in as_graph_element
    return self._as_graph_element_locked(obj, allow_tensor, allow_operation)
  File "D:\rachit\Blue book\Blue3\lib\site-packages\tensorflow\python\framework\ops.py", line 3567, in _as_graph_element_locked
    raise ValueError("Tensor %s is not an element of this graph." % obj)
ValueError: Tensor Tensor("Placeholder:0", shape=(8, 12), dtype=float32) is not an element of this graph.

During handling of the above exception, another exception occurred:

Traceback (most recent call last):
  File "D:\rachit\Blue book\handler\LoadModelService.py", line 31, in load_model
    LoadModelService.load_model_dict[filename] = pickle.load(open(filepath, 'rb'))
  File "D:\rachit\Blue book\Blue3\lib\site-packages\keras\engine\network.py", line 1266, in __setstate__
    model = saving.unpickle_model(state)
  File "D:\rachit\Blue book\Blue3\lib\site-packages\keras\engine\saving.py", line 435, in unpickle_model
    return _deserialize_model(f)
  File "D:\rachit\Blue book\Blue3\lib\site-packages\keras\engine\saving.py", line 287, in _deserialize_model
    K.batch_set_value(weight_value_tuples)
  File "D:\rachit\Blue book\Blue3\lib\site-packages\keras\backend\tensorflow_backend.py", line 2470, in batch_set_value
    get_session().run(assign_ops, feed_dict=feed_dict)
  File "D:\rachit\Blue book\Blue3\lib\site-packages\tensorflow\python\client\session.py", line 887, in run
    run_metadata_ptr)
  File "D:\rachit\Blue book\Blue3\lib\site-packages\tensorflow\python\client\session.py", line 1053, in _run
    'Cannot interpret feed_dict key as Tensor: ' + e.args[0])
TypeError: Cannot interpret feed_dict key as Tensor: Tensor Tensor("Placeholder:0", shape=(8, 12), dtype=float32) is not an element of this graph.
2018-11-02 15:28:48,004 - ErrorLogs - ERROR - EXCEPTION 403: NO such model "Model not deployed, Please deploy model"
Traceback (most recent call last):
  File "D:/rachit/Blue book/PC.py", line 320, in predict
    raise CE.ModelNotInMemory("Model not deployed, Please deploy model", 403)
CustomException.CustomException.ModelNotInMemory: Model not deployed, Please deploy model
2018-11-02 15:28:57,212 - ErrorLogs - ERROR - EXCEPTION 403: NO such model "Model not deployed, Please deploy model"
Traceback (most recent call last):
  File "D:/rachit/Blue book/PC.py", line 320, in predict
    raise CE.ModelNotInMemory("Model not deployed, Please deploy model", 403)
CustomException.CustomException.ModelNotInMemory: Model not deployed, Please deploy model
2018-11-02 15:29:04,862 - ErrorLogs - ERROR - EXCEPTION 500: Damm! Something Blew up
Traceback (most recent call last):
  File "D:\rachit\Blue book\Blue3\lib\site-packages\tensorflow\python\client\session.py", line 1050, in _run
    subfeed, allow_tensor=True, allow_operation=False)
  File "D:\rachit\Blue book\Blue3\lib\site-packages\tensorflow\python\framework\ops.py", line 3488, in as_graph_element
    return self._as_graph_element_locked(obj, allow_tensor, allow_operation)
  File "D:\rachit\Blue book\Blue3\lib\site-packages\tensorflow\python\framework\ops.py", line 3567, in _as_graph_element_locked
    raise ValueError("Tensor %s is not an element of this graph." % obj)
ValueError: Tensor Tensor("Placeholder:0", shape=(8, 12), dtype=float32) is not an element of this graph.

During handling of the above exception, another exception occurred:

Traceback (most recent call last):
  File "D:\rachit\Blue book\handler\LoadModelService.py", line 31, in load_model
    LoadModelService.load_model_dict[filename] = pickle.load(open(filepath, 'rb'))
  File "D:\rachit\Blue book\Blue3\lib\site-packages\keras\engine\network.py", line 1266, in __setstate__
    model = saving.unpickle_model(state)
  File "D:\rachit\Blue book\Blue3\lib\site-packages\keras\engine\saving.py", line 435, in unpickle_model
    return _deserialize_model(f)
  File "D:\rachit\Blue book\Blue3\lib\site-packages\keras\engine\saving.py", line 287, in _deserialize_model
    K.batch_set_value(weight_value_tuples)
  File "D:\rachit\Blue book\Blue3\lib\site-packages\keras\backend\tensorflow_backend.py", line 2470, in batch_set_value
    get_session().run(assign_ops, feed_dict=feed_dict)
  File "D:\rachit\Blue book\Blue3\lib\site-packages\tensorflow\python\client\session.py", line 887, in run
    run_metadata_ptr)
  File "D:\rachit\Blue book\Blue3\lib\site-packages\tensorflow\python\client\session.py", line 1053, in _run
    'Cannot interpret feed_dict key as Tensor: ' + e.args[0])
TypeError: Cannot interpret feed_dict key as Tensor: Tensor Tensor("Placeholder:0", shape=(8, 12), dtype=float32) is not an element of this graph.
2018-11-02 15:29:34,437 - ErrorLogs - ERROR - EXCEPTION 500: Damm! Something Blew up
Traceback (most recent call last):
  File "D:\rachit\Blue book\Blue3\lib\site-packages\tensorflow\python\client\session.py", line 1050, in _run
    subfeed, allow_tensor=True, allow_operation=False)
  File "D:\rachit\Blue book\Blue3\lib\site-packages\tensorflow\python\framework\ops.py", line 3488, in as_graph_element
    return self._as_graph_element_locked(obj, allow_tensor, allow_operation)
  File "D:\rachit\Blue book\Blue3\lib\site-packages\tensorflow\python\framework\ops.py", line 3567, in _as_graph_element_locked
    raise ValueError("Tensor %s is not an element of this graph." % obj)
ValueError: Tensor Tensor("Placeholder:0", shape=(8, 12), dtype=float32) is not an element of this graph.

During handling of the above exception, another exception occurred:

Traceback (most recent call last):
  File "D:\rachit\Blue book\handler\LoadModelService.py", line 31, in load_model
    LoadModelService.load_model_dict[filename] = pickle.load(open(filepath, 'rb'))
  File "D:\rachit\Blue book\Blue3\lib\site-packages\keras\engine\network.py", line 1266, in __setstate__
    model = saving.unpickle_model(state)
  File "D:\rachit\Blue book\Blue3\lib\site-packages\keras\engine\saving.py", line 435, in unpickle_model
    return _deserialize_model(f)
  File "D:\rachit\Blue book\Blue3\lib\site-packages\keras\engine\saving.py", line 287, in _deserialize_model
    K.batch_set_value(weight_value_tuples)
  File "D:\rachit\Blue book\Blue3\lib\site-packages\keras\backend\tensorflow_backend.py", line 2470, in batch_set_value
    get_session().run(assign_ops, feed_dict=feed_dict)
  File "D:\rachit\Blue book\Blue3\lib\site-packages\tensorflow\python\client\session.py", line 887, in run
    run_metadata_ptr)
  File "D:\rachit\Blue book\Blue3\lib\site-packages\tensorflow\python\client\session.py", line 1053, in _run
    'Cannot interpret feed_dict key as Tensor: ' + e.args[0])
TypeError: Cannot interpret feed_dict key as Tensor: Tensor Tensor("Placeholder:0", shape=(8, 12), dtype=float32) is not an element of this graph.
